<?xml version="1.0"?>
<robot name="manmaru" xmlns:xacro="http://ros.org/wiki/xacro">

   <xacro:macro name="default_inertial" params="mass">
      <inertial>
         <origin xyz="0 0 0" rpy="0 0 0"/>
         <mass value="${mass}" />
         <inertia ixx="1.0" ixy="0.0" ixz="0.0" iyy="1.0" iyz="0.0" izz="1.0" />
      </inertial>
   </xacro:macro>

   <xacro:macro name="wheel" params="prefix x y">
      <link name="${prefix}_wheel">
         <visual>
            <origin xyz="0 0 0" rpy="0 0 0" />
            <geometry>
               <mesh filename="package://manmaru_description/meshes/wheel.stl"/>
            </geometry>
         </visual>
         <collision>
            <origin xyz="0 0 0" rpy="0 0 0" />
            <geometry>
               <mesh filename="package://manmaru_description/meshes/wheel.stl"/>
            </geometry>
         </collision>
         <xacro:default_inertial mass="1"/>
      </link>

      <joint name="${prefix}_wheel_joint" type="continuous">
         <origin xyz="${x} ${y} 0" rpy="0 0 0"/>
         <axis xyz="0 1 0" rpy="0 0 0" />
         <parent link="trunk"/>
         <child link="${prefix}_wheel"/>
      </joint>

      <!-- This block provides Gazebo with information on a few additional physical properties. -->
      <gazebo reference="${prefix}_wheel">
         <mu1 value="200.0"/>
         <mu2 value="100.0"/>
         <kp value="1000000.0" />
         <kd value="10.0" />
      </gazebo>

      <!-- This block connects the wheel joint to an actuator (motor), which informs both
      simulation and visualization of the robot -->
      <transmission name="${prefix}_wheel_trans">
         <type>transmission_interface/SimpleTransmission</type>
         <actuator name="${prefix}_wheel_motor">
            <mechanicalReduction>1</mechanicalReduction>
         </actuator>
         <joint name="${prefix}_wheel_joint">
            <hardwareInterface>hardware_interface/VelocityJointInterface</hardwareInterface>
         </joint>
      </transmission>
   </xacro:macro>

   <!-- Trunk -->
   <link name="dummy"></link>
   <link name="trunk">
      <visual>
         <origin xyz="0 0 0" rpy="0 0 0" />
         <geometry>
            <mesh filename="package://manmaru_description/meshes/trunk.stl"/>
         </geometry>
      </visual>
      <collision>
         <origin xyz="0 0 0" rpy="0 0 0" />
         <geometry>
            <mesh filename="package://manmaru_description/meshes/trunk.stl"/>
         </geometry>
      </collision>
      <xacro:default_inertial mass="5"/>
   </link>
   <joint name="dummy_joint" type="fixed">
      <parent link="dummy"/>
      <child link="trunk"/>
   </joint>

   <!-- Four Wheels -->
   <xacro:wheel prefix="left_front"  x="0.04"  y="0.04"/>
   <xacro:wheel prefix="left_back"   x="0.04"  y="-0.04"/>
   <xacro:wheel prefix="right_front" x="-0.04" y="0.04"/>
   <xacro:wheel prefix="right_back"  x="-0.04" y="-0.04"/>

   <!-- LiDAR -->
   <xacro:include filename="lidar.urdf.xacro" />

   <!-- Manipulator -->
   <xacro:include filename="manipulator.urdf.xacro" />

   <!-- Gazebo plugins -->
   <xacro:include filename="gazebo.urdf" />

</robot>